Workbook

Sheet Instrucciones de uso
A1: INSTRUCCIONES DE USO Y DILIGENCIAMIENTO · HERRAMIENTA CF2
A2: Programa 22230071_v1 · Componente formativo 2 · Evaluación de alternativas de almacenamiento y reúso de agua lluvia. Esta guía está dirigida al aprendiz y debe leerse antes de modificar la hoja 4 y las curvas SRY.
A5: 1. PROPÓSITO FORMATIVO
A6: Transformar una serie mensual de precipitación previamente validada en una evaluación reproducible de captación, almacenamiento, suministro, déficit, rebose y desempeño del sistema. Al finalizar, el aprendiz debe comparar alternativas de tanque y demanda, interpretar fiabilidad, resiliencia y vulnerabilidad, y justificar técnicamente una configuración sin asumir que la mayor capacidad siempre es la mejor.
A9: 2. REQUISITOS DE ENTRADA
A10: 1 | B10: Utilice una serie mensual validada en CF1 y verifique que la unidad sea milímetros (mm). | G10: 4 | H10: Establezca el umbral de servicio y el objetivo de fiabilidad que utilizará para aceptar o rechazar una alternativa.
A11: 2 | B11: Defina área de captación (m²), coeficiente de escorrentía, eficiencia, pérdidas, almacenamiento inicial y capacidad del tanque (m³). | G11: 5 | H11: Prepare capacidades candidatas y factores de demanda para construir y comparar las curvas SRY.
A12: 3 | B12: Defina las demandas mensuales de sanitarios, riego y limpieza o justifique otra configuración de uso. | G12: 6 | H12: Si utiliza valores IPE, calcúlelos con una metodología válida y conserve la fuente. El libro solo los clasifica e interpreta.
A14: 3. CÓDIGO DE COLORES
A15: ENTRADA | D15: FÓRMULA | G15: ALERTA | J15: EJEMPLO
A16: Diligencie o reemplace datos | D16: Resultado automático; no sobrescribir | G16: Revise antes de avanzar | J16: Dato demostrativo; sustituir
A18: 4. RUTA DE DILIGENCIAMIENTO
A19: Paso | B19: Pestaña / bloque | D19: Acción del aprendiz | G19: Dónde diligenciar | J19: Control antes de continuar
A20: 1 | B20: Hoja 4 · Parámetros | D20: Reemplace los parámetros del caso didáctico y seleccione la configuración de uso. | G20: Celdas azules del bloque PARÁMETROS DE DISEÑO Y OPERACIÓN, especialmente B8:B18. | J20: Unidades coherentes: área en m², capacidades y demandas en m³, coeficientes y eficiencias entre 0 y 1.
A21: 2 | B21: Hoja 4 · Precipitación | D21: Transfiera desde CF1 únicamente la serie mensual validada y conserve la correspondencia fecha–mes–valor. | G21: Columna azul Precipitación (mm). Mantenga la estructura temporal del balance. | J21: No hay meses duplicados, desordenados o vacíos sin justificar; la serie corresponde al mismo sitio y periodo del análisis.
A22: 3 | B22: Hoja 4 · Demanda | D22: Diligencie o ajuste las demandas mensuales de sanitarios, riego y limpieza según el caso. | G22: Columnas azules de demanda y controles de configuración. | J22: La demanda es mensual, está en m³ y corresponde a la configuración seleccionada.
A23: 4 | B23: Hoja 4 · IPE | D23: Ingrese IPE-1 e IPE-3 solo cuando hayan sido calculados con una metodología técnicamente sustentada. | G23: Celdas azules K8, K9, O8 y O9. Las clasificaciones son automáticas. | J23: La escala y el periodo temporal están documentados. No se presenta la clasificación como cálculo del índice.
A24: 5 | B24: Hoja 4 · Balance | D24: Revise captación, almacenamiento, pérdidas, suministro, déficit y rebose mes a mes. | G24: Columnas verdes E:H y L:V son fórmulas; no las sobrescriba. | J24: Se cumple el balance: entrada y almacenamiento respetan la capacidad, el suministro no excede la demanda y no existen volúmenes negativos.
A25: 6 | B25: Hoja 4 · Indicadores | D25: Interprete fiabilidad, periodos de falla, resiliencia, vulnerabilidad, déficit máximo, duración media y rebose. | G25: Bloque RESULTADOS DEL SISTEMA SELECCIONADO y resumen anual. | J25: La conclusión CUMPLE/NO CUMPLE se contrasta con el objetivo y se explican las causas del desempeño.
A26: 7 | B26: Curvas SRY | D26: Modifique capacidades candidatas, configuración, factores de demanda, capacidad seleccionada y objetivo de fiabilidad. | G26: Celdas azules B8:B14 y E8:E12. E13 indica la ventana didáctica de 120 periodos y no debe modificarse. | J26: Compare curvas de suministro–rendimiento–almacenamiento y seleccione una alternativa viable, no solo la de mayor tamaño.
A27: 8 | B27: Soporte SRY | D27: Utilice esta pestaña para auditar cómo se construyen las curvas y verificar la trazabilidad de los resultados. | G27: Consulta únicamente. No modifique fórmulas ni valores de soporte. | J27: La alternativa elegida coincide con los datos de la hoja 4 y con la curva correspondiente a la demanda evaluada.
A29: 5. CÓMO INTERPRETAR LOS INDICADORES
A30: 1 | B30: Fiabilidad: proporción de periodos en los que el sistema satisface el criterio de servicio definido. | G30: 4 | H30: Déficit máximo y duración media: describen la severidad y persistencia de las fallas.
A31: 2 | B31: Resiliencia: capacidad de recuperación después de una falla; valores mayores indican recuperación más frecuente. | G31: 5 | H31: Rebose: agua captada que no puede almacenarse; puede indicar oportunidad de uso adicional o capacidad insuficiente.
A32: 3 | B32: Vulnerabilidad: magnitud del déficit durante las fallas; debe interpretarse con la unidad y la demanda del caso. | G32: 6 | H32: Curva SRY: relaciona almacenamiento, rendimiento o demanda y nivel de servicio para comparar alternativas.
A34: 6. CONFIGURACIONES DE DEMANDA DE LA HERRAMIENTA
A35: Uso único sanitarios: considera únicamente la demanda sanitaria. Úsela cuando el objetivo sea abastecer ese servicio de forma independiente. | G35: Uso múltiple variable: suma sanitarios, riego y limpieza según el patrón mensual ingresado. Úsela cuando la estacionalidad de la demanda sea relevante.
A38: Uso múltiple medio: representa una demanda conjunta constante basada en un promedio. Explique por qué esta simplificación es pertinente para el caso. | G38: Uso prioritario sanitarios + limpieza: representa usos esenciales antes que riego. Verifique y documente el criterio de prioridad aplicado.
A42: 7. REGLAS CRÍTICAS Y ERRORES FRECUENTES
A43: 1 | B43: No pegue fechas, encabezados ni unidades dentro de la columna numérica de precipitación. | G43: 4 | H43: La ventana SRY de 120 meses es didáctica; para un estudio técnico amplíe el análisis a toda la serie validada.
A44: 2 | B44: No sobrescriba celdas verdes ni la pestaña Soporte SRY; contienen cálculos enlazados. | G44: 5 | H44: Una capacidad mayor no es automáticamente óptima: compare mejora del servicio, rebose, costo y restricciones del sitio.
A45: 3 | B45: No compare alternativas con series, demandas u objetivos distintos sin declarar el cambio. | G45: 6 | H45: Los valores IPE deben provenir de un cálculo externo válido; esta herramienta no reemplaza ese procedimiento.
A47: 8. PRODUCTO ESPERADO DEL APRENDIZ
A48: Entregue el libro con parámetros y demandas justificadas, serie de CF1 transferida y verificada, balance mensual calculado, lectura de indicadores, curvas SRY comparadas y una conclusión técnica sobre la alternativa seleccionada. La conclusión debe indicar configuración, capacidad, demanda, fiabilidad alcanzada, fallas, rebose, limitaciones y recomendaciones. Nombre sugerido: CF2_Apellidos_Nombre_Ficha_Fecha.xlsx.
A52: 9. LISTA DE VERIFICACIÓN ANTES DE ENTREGAR
A53: ☐ | B53: La precipitación proviene de CF1, está en mm y conserva una secuencia mensual coherente.
A54: ☐ | B54: Área, coeficiente, eficiencia, pérdidas, capacidad, almacenamiento inicial y demandas tienen unidades correctas.
A55: ☐ | B55: No sobrescribí fórmulas y comprobé que el balance no produzca volúmenes negativos ni suministros superiores a la demanda.
A56: ☐ | B56: Interpreté fiabilidad, fallas, resiliencia, vulnerabilidad, déficit y rebose respecto del objetivo definido.
A57: ☐ | B57: Comparé capacidades y configuraciones en las curvas SRY con el mismo conjunto de supuestos.
...

Sheet Hoja 4 - Cálculo
A1: HERRAMIENTA CF2 · HOJA 4 · ALMACENAMIENTO, RENDIMIENTO Y FIABILIDAD
A2: Programa 22230071_v1 · RA2 · Integre una serie mensual validada de CF1, estime la entrada captada, ejecute el balance del tanque y evalúe fiabilidad, resiliencia, vulnerabilidad y rebose. Datos precargados: ejemplo didáctico.
A4: LEYENDA | B4: Entrada | C4: Fórmula | D4: Alerta | E4: Ejemplo | F4: Unidades en encabezado
A6: PARÁMETROS DE DISEÑO Y OPERACIÓN | J6: INTERPRETACIÓN DEL IPE · INGRESO DE RESULTADOS | S6: RESULTADOS DEL SISTEMA SELECCIONADO
A7: Parámetro | B7: Valor | D7: Reglas de configuración: uso único = sanitarios; uso múltiple = demanda media conjunta constante; uso prioritario = sanitarios + limpieza como servicio esencial; uso variable = suma mensual de sanitarios, riego y limpieza. Estas reglas son editables mediante las demandas de la matriz. | J7: Escala | K7: Valor IPE | L7: Clasificación | M7: Lectura temporal | N7: Escala | O7: Valor IPE | P7: Clasificación | Q7: Lectura temporal | S7: Indicador | T7: Resultado | U7: Unidad | V7: Indicador | W7: Resultado | X7: Unidad | Y7: Indicador | Z7: Resultado | AA7: Unidad | AB7: Indicador | AC7: Resultado | AD7: Unidad | AE7: Indicador | AF7: Resultado | AG7: Unidad | AH7: Indicador | AI7: Resultado | AJ7: Unidad | AK7: Estado
A8: Serie utilizada | B8: Ejemplo CF1 · 1981-2010 | J8: IPE-1 | K8: -1.4 | L8: =IF(K8="","Sin dato",IF(K8>=2,"Extremadamente húmedo",IF(K8>=1.5,"Severamente húmedo",IF(K8>=1,"Moderadamente húmedo",IF(K8>-1,"Cercano a normal",IF(K8>-1.5,"Moderadamente seco",IF(K8>-2,"Severamente seco","Extremadamente seco"))))))) -> Moderadamente seco | M8: Condición reciente | N8: IPE-6 | O8: -1.6 | P8: =IF(O8="","Sin dato",IF(O8>=2,"Extremadamente húmedo",IF(O8>=1.5,"Severamente húmedo",IF(O8>=1,"Moderadamente húmedo",IF(O8>-1,"Cercano a normal",IF(O8>-1.5,"Moderadamente seco",IF(O8>-2,"Severamente seco","Extremadamente seco"))))))) -> Severamente seco | Q8: Corto a mediano plazo | S8: Entrada captada | T8: =SUM(H25:H384) -> 7285.3245 | U8: m³ | V8: Demanda | W8: =SUM(L25:L384) -> 4950 | X8: m³ | Y8: Suministro | Z8: =SUM(P25:P384) -> 4844.889 | AA8: m³ | AB8: Fiabilidad | AC8: =COUNTIF(T25:T384,"Satisfactorio")/$B$18 -> 0.85 | AD8: % | AE8: Periodos de falla | AF8: =COUNTIF(T25:T384,"Falla") -> 54 | AG8: periodos | AH8: Resiliencia | AI8: =IF(AF8=0,1,SUM(U25:U384)/AF8) -> 0.68518519 | AJ8: probabilidad | AK8: =IF(AC8>=$B$17,"CUMPLE","NO CUMPLE") -> NO CUMPLE
A9: Configuración de uso | B9: Uso variable | J9: IPE-3 | K9: -0.8 | L9: =IF(K9="","Sin dato",IF(K9>=2,"Extremadamente húmedo",IF(K9>=1.5,"Severamente húmedo",IF(K9>=1,"Moderadamente húmedo",IF(K9>-1,"Cercano a normal",IF(K9>-1.5,"Moderadamente seco",IF(K9>-2,"Severamente seco","Extremadamente seco"))))))) -> Cercano a normal | M9: Condición estacional | N9: IPE-12 | O9: -2.1 | P9: =IF(O9="","Sin dato",IF(O9>=2,"Extremadamente húmedo",IF(O9>=1.5,"Severamente húmedo",IF(O9>=1,"Moderadamente húmedo",IF(O9>-1,"Cercano a normal",IF(O9>-1.5,"Moderadamente seco",IF(O9>-2,"Severamente seco","Extremadamente seco"))))))) -> Extremadamente seco | Q9: Condición acumulada | S9: Déficit total | T9: =SUM(S25:S384) -> 105.11103 | U9: m³ | V9: Vulnerabilidad media | W9: =IF(AI9=0,0,T9/AI9) -> 2.8408386 | X9: m³/evento | Y9: Déficit máximo | Z9: =MAX(S25:S384) -> 4.0610275 | AA9: m³/periodo | AB9: Duración media | AC9: =IF(AI9=0,0,AF8/AI9) -> 1.4594595 | AD9: periodos | AE9: Rebose | AF9: =SUM(R25:R384) -> 2264.807 | AG9: m³ | AH9: Eventos de falla | AI9: =SUM(V25:V384) -> 37 | AJ9: eventos
A10: Capacidad del tanque (m³) | B10: 5 | J10: Interpretación integrada | K10: ="La escala corta presenta "&LOWER(L8)&"; la escala larga presenta "&LOWER(P9)&". Evalúe la persistencia antes de dimensionar el almacenamiento." -> La escala corta presenta moderadamente seco; la escala larga presenta extremadamente seco. Evalúe la persistencia antes de dimensionar el almacenamiento. | S10: Almacenamiento medio | T10: =AVERAGE(Q25:Q384) -> 3.4752795 | U10: m³ | V10: Utilización del tanque | W10: =IF($B$10=0,0,T10/$B$10) -> 0.69505589 | X10: % | Y10: Fiabilidad objetivo | Z10: =$B$17 -> 0.9 | AA10: % | AB10: Capacidad | AC10: =$B$10 -> 5 | AD10: m³ | AE10: Configuración | AF10: =$B$9 -> Uso variable | AG10: tipo | AH10: Conclusión | AI10: =IF(AC8>=$B$17,"Alternativa técnicamente viable según la meta definida","Ajustar capacidad, demanda o regla de operación") -> Ajustar capacidad, demanda o regla de operación
A11: Almacenamiento inicial (m³) | B11: 0 | J11: Nota | K11: La hoja interpreta valores IPE ya calculados mediante metodología válida; no sustituye el ajuste gamma ni la transformación normal descritos por la OMM.
A12: Área de captación (m²) | B12: 250 | J12: Uso | K12: Utilice IPE-1/3 para condiciones recientes y IPE-6/12 para persistencia con posible incidencia en el almacenamiento.
A13: Coeficiente de escorrentía | B13: 0.85
A14: Eficiencia de captación | B14: 0.9 | D14: Volumen captado: Q = P(mm) × A(m²) × C × E / 1000. Balance: almacenamiento inicial + entrada − pérdidas − suministro − rebose = almacenamiento final, sujeto a 0 ≤ S ≤ Smax.
A15: Pérdidas del periodo | B15: 0.02
A16: Umbral de servicio | B16: 1
A17: Fiabilidad objetivo | B17: 0.9
A18: Número de periodos | B18: 360
A21: BALANCE MENSUAL DEL TANQUE · DATOS DE ENTRADA Y RESULTADOS | X21: RESUMEN ANUAL DEL BALANCE
A24: Fecha | B24: Año | C24: Mes | D24: Precipitación (mm) | E24: Área (m²) | F24: Coef. C | G24: Eficiencia | H24: Entrada Q (m³) | I24: Dem. sanitarios | J24: Dem. riego | K24: Dem. limpieza | L24: Demanda aplicable | M24: Almac. inicial | N24: Pérdidas | O24: Disponible neto | P24: Suministro Y | Q24: Almac. final | R24: Rebose | S24: Déficit | T24: Estado | U24: Recuperación F→S | V24: Inicio evento | X24: Año | Y24: Entrada (m³) | Z24: Demanda (m³) | AA24: Suministro (m³) | AB24: Fiabilidad
A25: 29587 | B25: 1981 | C25: Enero | D25: 67.2 | E25: ='Hoja 4 - Cálculo'!$B$12 -> 250 | F25: ='Hoja 4 - Cálculo'!$B$13 -> 0.85 | G25: ='Hoja 4 - Cálculo'!$B$14 -> 0.9 | H25: =D25*E25*F25*G25/1000 -> 12.852 | I25: 8 | J25: 6 | K25: 2 | L25: =IF($B$9="Uso único",I25,IF($B$9="Uso múltiple",AVERAGE($I$25:$I$384)+AVERAGE($J$25:$J$384)+AVERAGE($K$25:$K$384),IF($B$9="Uso prioritario",I25+K25,I25+J25+K25))) -> 16 | M25: =$B$11 -> 0 | N25: =MIN(M25+H25,(M25+H25)*$B$15) -> 0.25704 | O25: =MAX(0,M25+H25-N25) -> 12.59496 | P25: =MIN(L25,O25) -> 12.59496 | Q25: =MIN($B$10,MAX(0,O25-P25)) -> 0 | R25: =MAX(0,O25-P25-$B$10) -> 0 | S25: =MAX(0,L25-P25) -> 3.40504 | T25: =IF(P25>=L25*$B$16,"Satisfactorio","Falla") -> Falla | U25: =0 -> 0 | V25: =IF(T25="Falla",1,0) -> 1 | X25: 1981 | Y25: =SUMIF($B$25:$B$384,X25,$H$25:$H$384) -> 238.79475 | Z25: =SUMIF($B$25:$B$384,X25,$L$25:$L$384) -> 165 | AA25: =SUMIF($B$25:$B$384,X25,$P$25:$P$384) -> 158.7813 | AB25: =COUNTIFS($B$25:$B$384,X25,$T$25:$T$384,"Satisfactorio")/COUNTIF($B$25:$B$384,X25) -> 0.75
A26: 29618 | B26: 1981 | C26: Febrero | D26: 76.5 | E26: ='Hoja 4 - Cálculo'!$B$12 -> 250 | F26: ='Hoja 4 - Cálculo'!$B$13 -> 0.85 | G26: ='Hoja 4 - Cálculo'!$B$14 -> 0.9 | H26: =D26*E26*F26*G26/1000 -> 14.630625 | I26: 8 | J26: 6 | K26: 2 | L26: =IF($B$9="Uso único",I26,IF($B$9="Uso múltiple",AVERAGE($I$25:$I$384)+AVERAGE($J$25:$J$384)+AVERAGE($K$25:$K$384),IF($B$9="Uso prioritario",I26+K26,I26+J26+K26))) -> 16 | M26: =Q25 -> 0 | N26: =MIN(M26+H26,(M26+H26)*$B$15) -> 0.2926125 | O26: =MAX(0,M26+H26-N26) -> 14.338012 | P26: =MIN(L26,O26) -> 14.338012 | Q26: =MIN($B$10,MAX(0,O26-P26)) -> 0 | R26: =MAX(0,O26-P26-$B$10) -> 0 | S26: =MAX(0,L26-P26) -> 1.6619875 | T26: =IF(P26>=L26*$B$16,"Satisfactorio","Falla") -> Falla | U26: =IF(AND(T25="Falla",T26="Satisfactorio"),1,0) -> 0 | V26: =IF(AND(T26="Falla",T25<>"Falla"),1,0) -> 0 | X26: 1982 | Y26: =SUMIF($B$25:$B$384,X26,$H$25:$H$384) -> 265.89488 | Z26: =SUMIF($B$25:$B$384,X26,$L$25:$L$384) -> 165 | AA26: =SUMIF($B$25:$B$384,X26,$P$25:$P$384) -> 165 | AB26: =COUNTIFS($B$25:$B$384,X26,$T$25:$T$384,"Satisfactorio")/COUNTIF($B$25:$B$384,X26) -> 1
A27: 29646 | B27: 1981 | C27: Marzo | D27: 110.4 | E27: ='Hoja 4 - Cálculo'!$B$12 -> 250 | F27: ='Hoja 4 - Cálculo'!$B$13 -> 0.85 | G27: ='Hoja 4 - Cálculo'!$B$14 -> 0.9 | H27: =D27*E27*F27*G27/1000 -> 21.114 | I27: 8 | J27: 6 | K27: 2 | L27: =IF($B$9="Uso único",I27,IF($B$9="Uso múltiple",AVERAGE($I$25:$I$384)+AVERAGE($J$25:$J$384)+AVERAGE($K$25:$K$384),IF($B$9="Uso prioritario",I27+K27,I27+J27+K27))) -> 16 | M27: =Q26 -> 0 | N27: =MIN(M27+H27,(M27+H27)*$B$15) -> 0.42228 | O27: =MAX(0,M27+H27-N27) -> 20.69172 | P27: =MIN(L27,O27) -> 16 | Q27: =MIN($B$10,MAX(0,O27-P27)) -> 4.69172 | R27: =MAX(0,O27-P27-$B$10) -> 0 | S27: =MAX(0,L27-P27) -> 0 | T27: =IF(P27>=L27*$B$16,"Satisfactorio","Falla") -> Satisfactorio | U27: =IF(AND(T26="Falla",T27="Satisfactorio"),1,0) -> 1 | V27: =IF(AND(T27="Falla",T26<>"Falla"),1,0) -> 0 | X27: 1983 | Y27: =SUMIF($B$25:$B$384,X27,$H$25:$H$384) -> 258.111 | Z27: =SUMIF($B$25:$B$384,X27,$L$25:$L$384) -> 165 | AA27: =SUMIF($B$25:$B$384,X27,$P$25:$P$384) -> 164.43622 | AB27: =COUNTIFS($B$25:$B$384,X27,$T$25:$T$384,"Satisfactorio")/COUNTIF($B$25:$B$384,X27) -> 0.91666667
A28: 29677 | B28: 1981 | C28: Abril | D28: 153.1 | E28: ='Hoja 4 - Cálculo'!$B$12 -> 250 | F28: ='Hoja 4 - Cálculo'!$B$13 -> 0.85 | G28: ='Hoja 4 - Cálculo'!$B$14 -> 0.9 | H28: =D28*E28*F28*G28/1000 -> 29.280375 | I28: 8 | J28: 1.5 | K28: 2 | L28: =IF($B$9="Uso único",I28,IF($B$9="Uso múltiple",AVERAGE($I$25:$I$384)+AVERAGE($J$25:$J$384)+AVERAGE($K$25:$K$384),IF($B$9="Uso prioritario",I28+K28,I28+J28+K28))) -> 11.5 | M28: =Q27 -> 4.69172 | N28: =MIN(M28+H28,(M28+H28)*$B$15) -> 0.6794419 | O28: =MAX(0,M28+H28-N28) -> 33.292653 | P28: =MIN(L28,O28) -> 11.5 | Q28: =MIN($B$10,MAX(0,O28-P28)) -> 5 | R28: =MAX(0,O28-P28-$B$10) -> 16.792653 | S28: =MAX(0,L28-P28) -> 0 | T28: =IF(P28>=L28*$B$16,"Satisfactorio","Falla") -> Satisfactorio | U28: =IF(AND(T27="Falla",T28="Satisfactorio"),1,0) -> 0 | V28: =IF(AND(T28="Falla",T27<>"Falla"),1,0) -> 0 | X28: 1984 | Y28: =SUMIF($B$25:$B$384,X28,$H$25:$H$384) -> 223.533 | Z28: =SUMIF($B$25:$B$384,X28,$L$25:$L$384) -> 165 | AA28: =SUMIF($B$25:$B$384,X28,$P$25:$P$384) -> 159.73619 | AB28: =COUNTIFS($B$25:$B$384,X28,$T$25:$T$384,"Satisfactorio")/COUNTIF($B$25:$B$384,X28) -> 0.75
A29: 29707 | B29: 1981 | C29: Mayo | D29: 136.2 | E29: ='Hoja 4 - Cálculo'!$B$12 -> 250 | F29: ='Hoja 4 - Cálculo'!$B$13 -> 0.85 | G29: ='Hoja 4 - Cálculo'!$B$14 -> 0.9 | H29: =D29*E29*F29*G29/1000 -> 26.04825 | I29: 8 | J29: 1.5 | K29: 2 | L29: =IF($B$9="Uso único",I29,IF($B$9="Uso múltiple",AVERAGE($I$25:$I$384)+AVERAGE($J$25:$J$384)+AVERAGE($K$25:$K$384),IF($B$9="Uso prioritario",I29+K29,I29+J29+K29))) -> 11.5 | M29: =Q28 -> 5 | N29: =MIN(M29+H29,(M29+H29)*$B$15) -> 0.620965 | O29: =MAX(0,M29+H29-N29) -> 30.427285 | P29: =MIN(L29,O29) -> 11.5 | Q29: =MIN($B$10,MAX(0,O29-P29)) -> 5 | R29: =MAX(0,O29-P29-$B$10) -> 13.927285 | S29: =MAX(0,L29-P29) -> 0 | T29: =IF(P29>=L29*$B$16,"Satisfactorio","Falla") -> Satisfactorio | U29: =IF(AND(T28="Falla",T29="Satisfactorio"),1,0) -> 0 | V29: =IF(AND(T29="Falla",T28<>"Falla"),1,0) -> 0 | X29: 1985 | Y29: =SUMIF($B$25:$B$384,X29,$H$25:$H$384) -> 219.22987 | Z29: =SUMIF($B$25:$B$384,X29,$L$25:$L$384) -> 165 | AA29: =SUMIF($B$25:$B$384,X29,$P$25:$P$384) -> 156.78125 | AB29: =COUNTIFS($B$25:$B$384,X29,$T$25:$T$384,"Satisfactorio")/COUNTIF($B$25:$B$384,X29) -> 0.75
A30: 29738 | B30: 1981 | C30: Junio | D30: 81.7 | E30: ='Hoja 4 - Cálculo'!$B$12 -> 250 | F30: ='Hoja 4 - Cálculo'!$B$13 -> 0.85 | G30: ='Hoja 4 - Cálculo'!$B$14 -> 0.9 | H30: =D30*E30*F30*G30/1000 -> 15.625125 | I30: 8 | J30: 1.5 | K30: 2 | L30: =IF($B$9="Uso único",I30,IF($B$9="Uso múltiple",AVERAGE($I$25:$I$384)+AVERAGE($J$25:$J$384)+AVERAGE($K$25:$K$384),IF($B$9="Uso prioritario",I30+K30,I30+J30+K30))) -> 11.5 | M30: =Q29 -> 5 | N30: =MIN(M30+H30,(M30+H30)*$B$15) -> 0.4125025 | O30: =MAX(0,M30+H30-N30) -> 20.212623 | P30: =MIN(L30,O30) -> 11.5 | Q30: =MIN($B$10,MAX(0,O30-P30)) -> 5 | R30: =MAX(0,O30-P30-$B$10) -> 3.7126225 | S30: =MAX(0,L30-P30) -> 0 | T30: =IF(P30>=L30*$B$16,"Satisfactorio","Falla") -> Satisfactorio | U30: =IF(AND(T29="Falla",T30="Satisfactorio"),1,0) -> 0 | V30: =IF(AND(T30="Falla",T29<>"Falla"),1,0) -> 0 | X30: 1986 | Y30: =SUMIF($B$25:$B$384,X30,$H$25:$H$384) -> 249.96375 | Z30: =SUMIF($B$25:$B$384,X30,$L$25:$L$384) -> 165 | AA30: =SUMIF($B$25:$B$384,X30,$P$25:$P$384) -> 163.17145 | AB30: =COUNTIFS($B$25:$B$384,X30,$T$25:$T$384,"Satisfactorio")/COUNTIF($B$25:$B$384,X30) -> 0.83333333
A31: 29768 | B31: 1981 | C31: Julio | D31: 66.9 | E31: ='Hoja 4 - Cálculo'!$B$12 -> 250 | F31: ='Hoja 4 - Cálculo'!$B$13 -> 0.85 | G31: ='Hoja 4 - Cálculo'!$B$14 -> 0.9 | H31: =D31*E31*F31*G31/1000 -> 12.794625 | I31: 8 | J31: 6 | K31: 2 | L31: =IF($B$9="Uso único",I31,IF($B$9="Uso múltiple",AVERAGE($I$25:$I$384)+AVERAGE($J$25:$J$384)+AVERAGE($K$25:$K$384),IF($B$9="Uso prioritario",I31+K31,I31+J31+K31))) -> 16 | M31: =Q30 -> 5 | N31: =MIN(M31+H31,(M31+H31)*$B$15) -> 0.3558925 | O31: =MAX(0,M31+H31-N31) -> 17.438733 | P31: =MIN(L31,O31) -> 16 | Q31: =MIN($B$10,MAX(0,O31-P31)) -> 1.4387325 | R31: =MAX(0,O31-P31-$B$10) -> 0 | S31: =MAX(0,L31-P31) -> 0 | T31: =IF(P31>=L31*$B$16,"Satisfactorio","Falla") -> Satisfactorio | U31: =IF(AND(T30="Falla",T31="Satisfactorio"),1,0) -> 0 | V31: =IF(AND(T31="Falla",T30<>"Falla"),1,0) -> 0 | X31: 1987 | Y31: =SUMIF($B$25:$B$384,X31,$H$25:$H$384) -> 269.68162 | Z31: =SUMIF($B$25:$B$384,X31,$L$25:$L$384) -> 165 | AA31: =SUMIF($B$25:$B$384,X31,$P$25:$P$384) -> 165 | AB31: =COUNTIFS($B$25:$B$384,X31,$T$25:$T$384,"Satisfactorio")/COUNTIF($B$25:$B$384,X31) -> 1
A32: 29799 | B32: 1981 | C32: Agosto | D32: 71.7 | E32: ='Hoja 4 - Cálculo'!$B$12 -> 250 | F32: ='Hoja 4 - Cálculo'!$B$13 -> 0.85 | G32: ='Hoja 4 - Cálculo'!$B$14 -> 0.9 | H32: =D32*E32*F32*G32/1000 -> 13.712625 | I32: 8 | J32: 6 | K32: 2 | L32: =IF($B$9="Uso único",I32,IF($B$9="Uso múltiple",AVERAGE($I$25:$I$384)+AVERAGE($J$25:$J$384)+AVERAGE($K$25:$K$384),IF($B$9="Uso prioritario",I32+K32,I32+J32+K32))) -> 16 | M32: =Q31 -> 1.4387325 | N32: =MIN(M32+H32,(M32+H32)*$B$15) -> 0.30302715 | O32: =MAX(0,M32+H32-N32) -> 14.84833 | P32: =MIN(L32,O32) -> 14.84833 | Q32: =MIN($B$10,MAX(0,O32-P32)) -> 0 | R32: =MAX(0,O32-P32-$B$10) -> 0 | S32: =MAX(0,L32-P32) -> 1.1516697 | T32: =IF(P32>=L32*$B$16,"Satisfactorio","Falla") -> Falla | U32: =IF(AND(T31="Falla",T32="Satisfactorio"),1,0) -> 0 | V32: =IF(AND(T32="Falla",T31<>"Falla"),1,0) -> 1 | X32: 1988 | Y32: =SUMIF($B$25:$B$384,X32,$H$25:$H$384) -> 250.0785 | Z32: =SUMIF($B$25:$B$384,X32,$L$25:$L$384) -> 165 | AA32: =SUMIF($B$25:$B$384,X32,$P$25:$P$384) -> 164.79445 | AB32: =COUNTIFS($B$25:$B$384,X32,$T$25:$T$384,"Satisfactorio")/COUNTIF($B$25:$B$384,X32) -> 0.91666667
A33: 29830 | B33: 1981 | C33: Septiembre | D33: 115.4 | E33: ='Hoja 4 - Cálculo'!$B$12 -> 250 | F33: ='Hoja 4 - Cálculo'!$B$13 -> 0.85 | G33: ='Hoja 4 - Cálculo'!$B$14 -> 0.9 | H33: =D33*E33*F33*G33/1000 -> 22.07025 | I33: 8 | J33: 1.5 | K33: 2 | L33: =IF($B$9="Uso único",I33,IF($B$9="Uso múltiple",AVERAGE($I$25:$I$384)+AVERAGE($J$25:$J$384)+AVERAGE($K$25:$K$384),IF($B$9="Uso prioritario",I33+K33,I33+J33+K33))) -> 11.5 | M33: =Q32 -> 0 | N33: =MIN(M33+H33,(M33+H33)*$B$15) -> 0.441405 | O33: =MAX(0,M33+H33-N33) -> 21.628845 | P33: =MIN(L33,O33) -> 11.5 | Q33: =MIN($B$10,MAX(0,O33-P33)) -> 5 | R33: =MAX(0,O33-P33-$B$10) -> 5.128845 | S33: =MAX(0,L33-P33) -> 0 | T33: =IF(P33>=L33*$B$16,"Satisfactorio","Falla") -> Satisfactorio | U33: =IF(AND(T32="Falla",T33="Satisfactorio"),1,0) -> 1 | V33: =IF(AND(T33="Falla",T32<>"Falla"),1,0) -> 0 | X33: 1989 | Y33: =SUMIF($B$25:$B$384,X33,$H$25:$H$384) -> 220.12875 | Z33: =SUMIF($B$25:$B$384,X33,$L$25:$L$384) -> 165 | AA33: =SUMIF($B$25:$B$384,X33,$P$25:$P$384) -> 158.97038 | AB33: =COUNTIFS($B$25:$B$384,X33,$T$25:$T$384,"Satisfactorio")/COUNTIF($B$25:$B$384,X33) -> 0.83333333
A34: 29860 | B34: 1981 | C34: Octubre | D34: 155.7 | E34: ='Hoja 4 - Cálculo'!$B$12 -> 250 | F34: ='Hoja 4 - Cálculo'!$B$13 -> 0.85 | G34: ='Hoja 4 - Cálculo'!$B$14 -> 0.9 | H34: =D34*E34*F34*G34/1000 -> 29.777625 | I34: 8 | J34: 1.5 | K34: 2 | L34: =IF($B$9="Uso único",I34,IF($B$9="Uso múltiple",AVERAGE($I$25:$I$384)+AVERAGE($J$25:$J$384)+AVERAGE($K$25:$K$384),IF($B$9="Uso prioritario",I34+K34,I34+J34+K34))) -> 11.5 | M34: =Q33 -> 5 | N34: =MIN(M34+H34,(M34+H34)*$B$15) -> 0.6955525 | O34: =MAX(0,M34+H34-N34) -> 34.082073 | P34: =MIN(L34,O34) -> 11.5 | Q34: =MIN($B$10,MAX(0,O34-P34)) -> 5 | R34: =MAX(0,O34-P34-$B$10) -> 17.582073 | S34: =MAX(0,L34-P34) -> 0 | T34: =IF(P34>=L34*$B$16,"Satisfactorio","Falla") -> Satisfactorio | U34: =IF(AND(T33="Falla",T34="Satisfactorio"),1,0) -> 0 | V34: =IF(AND(T34="Falla",T33<>"Falla"),1,0) -> 0 | X34: 1990 | Y34: =SUMIF($B$25:$B$384,X34,$H$25:$H$384) -> 224.24062 | Z34: =SUMIF($B$25:$B$384,X34,$L$25:$L$384) -> 165 | AA34: =SUMIF($B$25:$B$384,X34,$P$25:$P$384) -> 158.07298 | AB34: =COUNTIFS($B$25:$B$384,X34,$T$25:$T$384,"Satisfactorio")/COUNTIF($B$25:$B$384,X34) -> 0.75
A35: 29891 | B35: 1981 | C35: Noviembre | D35: 133.4 | E35: ='Hoja 4 - Cálculo'!$B$12 -> 250 | F35: ='Hoja 4 - Cálculo'!$B$13 -> 0.85 | G35: ='Hoja 4 - Cálculo'!$B$14 -> 0.9 | H35: =D35*E35*F35*G35/1000 -> 25.51275 | I35: 8 | J35: 1.5 | K35: 2 | L35: =IF($B$9="Uso único",I35,IF($B$9="Uso múltiple",AVERAGE($I$25:$I$384)+AVERAGE($J$25:$J$384)+AVERAGE($K$25:$K$384),IF($B$9="Uso prioritario",I35+K35,I35+J35+K35))) -> 11.5 | M35: =Q34 -> 5 | N35: =MIN(M35+H35,(M35+H35)*$B$15) -> 0.610255 | O35: =MAX(0,M35+H35-N35) -> 29.902495 | P35: =MIN(L35,O35) -> 11.5 | Q35: =MIN($B$10,MAX(0,O35-P35)) -> 5 | R35: =MAX(0,O35-P35-$B$10) -> 13.402495 | S35: =MAX(0,L35-P35) -> 0 | T35: =IF(P35>=L35*$B$16,"Satisfactorio","Falla") -> Satisfactorio | U35: =IF(AND(T34="Falla",T35="Satisfactorio"),1,0) -> 0 | V35: =IF(AND(T35="Falla",T34<>"Falla"),1,0) -> 0 | X35: 1991 | Y35: =SUMIF($B$25:$B$384,X35,$H$25:$H$384) -> 256.48538 | Z35: =SUMIF($B$25:$B$384,X35,$L$25:$L$384) -> 165 | AA35: =SUMIF($B$25:$B$384,X35,$P$25:$P$384) -> 163.46121 | AB35: =COUNTIFS($B$25:$B$384,X35,$T$25:$T$384,"Satisfactorio")/COUNTIF($B$25:$B$384,X35) -> 0.83333333
A36: 29921 | B36: 1981 | C36: Diciembre | D36: 80.4 | E36: ='Hoja 4 - Cálculo'!$B$12 -> 250 | F36: ='Hoja 4 - Cálculo'!$B$13 -> 0.85 | G36: ='Hoja 4 - Cálculo'!$B$14 -> 0.9 | H36: =D36*E36*F36*G36/1000 -> 15.3765 | I36: 8 | J36: 6 | K36: 2 | L36: =IF($B$9="Uso único",I36,IF($B$9="Uso múltiple",AVERAGE($I$25:$I$384)+AVERAGE($J$25:$J$384)+AVERAGE($K$25:$K$384),IF($B$9="Uso prioritario",I36+K36,I36+J36+K36))) -> 16 | M36: =Q35 -> 5 | N36: =MIN(M36+H36,(M36+H36)*$B$15) -> 0.40753 | O36: =MAX(0,M36+H36-N36) -> 19.96897 | P36: =MIN(L36,O36) -> 16 | Q36: =MIN($B$10,MAX(0,O36-P36)) -> 3.96897 | R36: =MAX(0,O36-P36-$B$10) -> 0 | S36: =MAX(0,L36-P36) -> 0 | T36: =IF(P36>=L36*$B$16,"Satisfactorio","Falla") -> Satisfactorio | U36: =IF(AND(T35="Falla",T36="Satisfactorio"),1,0) -> 0 | V36: =IF(AND(T36="Falla",T35<>"Falla"),1,0) -> 0 | X36: 1992 | Y36: =SUMIF($B$25:$B$384,X36,$H$25:$H$384) -> 267.99863 | Z36: =SUMIF($B$25:$B$384,X36,$L$25:$L$384) -> 165 | AA36: =SUMIF($B$25:$B$384,X36,$P$25:$P$384) -> 165 | AB36: =COUNTIFS($B$25:$B$384,X36,$T$25:$T$384,"Satisfactorio")/COUNTIF($B$25:$B$384,X36) -> 1
A37: 29952 | B37: 1982 | C37: Enero | D37: 72.2 | E37: ='Hoja 4 - Cálculo'!$B$12 -> 250 | F37: ='Hoja 4 - Cálculo'!$B$13 -> 0.85 | G37: ='Hoja 4 - Cálculo'!$B$14 -> 0.9 | H37: =D37*E37*F37*G37/1000 -> 13.80825 | I37: 8 | J37: 6 | K37: 2 | L37: =IF($B$9="Uso único",I37,IF($B$9="Uso múltiple",AVERAGE($I$25:$I$384)+AVERAGE($J$25:$J$384)+AVERAGE($K$25:$K$384),IF($B$9="Uso prioritario",I37+K37,I37+J37+K37))) -> 16 | M37: =Q36 -> 3.96897 | N37: =MIN(M37+H37,(M37+H37)*$B$15) -> 0.3555444 | O37: =MAX(0,M37+H37-N37) -> 17.421676 | P37: =MIN(L37,O37) -> 16 | Q37: =MIN($B$10,MAX(0,O37-P37)) -> 1.4216756 | R37: =MAX(0,O37-P37-$B$10) -> 0 | S37: =MAX(0,L37-P37) -> 0 | T37: =IF(P37>=L37*$B$16,"Satisfactorio","Falla") -> Satisfactorio | U37: =IF(AND(T36="Falla",T37="Satisfactorio"),1,0) -> 0 | V37: =IF(AND(T37="Falla",T36<>"Falla"),1,0) -> 0 | X37: 1993 | Y37: =SUMIF($B$25:$B$384,X37,$H$25:$H$384) -> 242.10337 | Z37: =SUMIF($B$25:$B$384,X37,$L$25:$L$384) -> 165 | AA37: =SUMIF($B$25:$B$384,X37,$P$25:$P$384) -> 163.36065 | AB37: =COUNTIFS($B$25:$B$384,X37,$T$25:$T$384,"Satisfactorio")/COUNTIF($B$25:$B$384,X37) -> 0.91666667
... A41: 30072 | B41: 1982 | C41: Mayo | D41: 153.2 | E41: ='Hoja 4 - Cálculo'!$B$12 -> 250 | F41: ='Hoja 4 - Cálculo'!$B$13 -> 0.85 | G41: ='Hoja 4 - Cálculo'!$B$14 -> 0.9 | H41: =D41*E41*F41*G41/1000 -> 29.2995 | I41: 8 | J41: 1.5 | K41: 2 | L41: =IF($B$9="Uso único",I41,IF($B$9="Uso múltiple",AVERAGE($I$25:$I$384)+AVERAGE($J$25:$J$384)+AVERAGE($K$25:$K$384),IF($B$9="Uso prioritario",I41+K41,I41+J41+K41))) -> 11.5 | M41: =Q40 -> 5 | N41: =MIN(M41+H41,(M41+H41)*$B$15) -> 0.68599 | O41: =MAX(0,M41+H41-N41) -> 33.61351 | P41: =MIN(L41,O41) -> 11.5 | Q41: =MIN($B$10,MAX(0,O41-P41)) -> 5 | R41: =MAX(0,O41-P41-$B$10) -> 17.11351 | S41: =MAX(0,L41-P41) -> 0 | T41: =IF(P41>=L41*$B$16,"Satisfactorio","Falla") -> Satisfactorio | U41: =IF(AND(T40="Falla",T41="Satisfactorio"),1,0) -> 0 | V41: =IF(AND(T41="Falla",T40<>"Falla"),1,0) -> 0 | X41: 1997 | Y41: =SUMIF($B$25:$B$384,X41,$H$25:$H$384) -> 276.71962 | Z41: =SUMIF($B$25:$B$384,X41,$L$25:$L$384) -> 165 | AA41: =SUMIF($B$25:$B$384,X41,$P$25:$P$384) -> 165 | AB41: =COUNTIFS($B$25:$B$384,X41,$T$25:$T$384,"Satisfactorio")/COUNTIF($B$25:$B$384,X41) -> 1
A42: 30103 | B42: 1982 | C42: Junio | D42: 95.8 | E42: ='Hoja 4 - Cálculo'!$B$12 -> 250 | F42: ='Hoja 4 - Cálculo'!$B$13 -> 0.85 | G42: ='Hoja 4 - Cálculo'!$B$14 -> 0.9 | H42: =D42*E42*F42*G42/1000 -> 18.32175 | I42: 8 | J42: 1.5 | K42: 2 | L42: =IF($B$9="Uso único",I42,IF($B$9="Uso múltiple",AVERAGE($I$25:$I$384)+AVERAGE($J$25:$J$384)+AVERAGE($K$25:$K$384),IF($B$9="Uso prioritario",I42+K42,I42+J42+K42))) -> 11.5 | M42: =Q41 -> 5 | N42: =MIN(M42+H42,(M42+H42)*$B$15) -> 0.466435 | O42: =MAX(0,M42+H42-N42) -> 22.855315 | P42: =MIN(L42,O42) -> 11.5 | Q42: =MIN($B$10,MAX(0,O42-P42)) -> 5 | R42: =MAX(0,O42-P42-$B$10) -> 6.355315 | S42: =MAX(0,L42-P42) -> 0 | T42: =IF(P42>=L42*$B$16,"Satisfactorio","Falla") -> Satisfactorio | U42: =IF(AND(T41="Falla",T42="Satisfactorio"),1,0) -> 0 | V42: =IF(AND(T42="Falla",T41<>"Falla"),1,0) -> 0 | X42: 1998 | Y42: =SUMIF($B$25:$B$384,X42,$H$25:$H$384) -> 231.62287 | Z42: =SUMIF($B$25:$B$384,X42,$L$25:$L$384) -> 165 | AA42: =SUMIF($B$25:$B$384,X42,$P$25:$P$384) -> 162.05492 | AB42: =COUNTIFS($B$25:$B$384,X42,$T$25:$T$384,"Satisfactorio")/COUNTIF($B$25:$B$384,X42) -> 0.83333333 | AD42: Decisión del aprendiz: compare la fiabilidad obtenida con la meta, revise déficit, duración de fallas y rebose. Una capacidad mayor no es automáticamente óptima: identifique cuándo las mejoras son marginales y contraste configuraciones en la hoja Curvas SRY.
A43: 30133 | B43: 1982 | C43: Julio | D43: 80.4 | E43: ='Hoja 4 - Cálculo'!$B$12 -> 250 | F43: ='Hoja 4 - Cálculo'!$B$13 -> 0.85 | G43: ='Hoja 4 - Cálculo'!$B$14 -> 0.9 | H43: =D43*E43*F43*G43/1000 -> 15.3765 | I43: 8 | J43: 6 | K43: 2 | L43: =IF($B$9="Uso único",I43,IF($B$9="Uso múltiple",AVERAGE($I$25:$I$384)+AVERAGE($J$25:$J$384)+AVERAGE($K$25:$K$384),IF($B$9="Uso prioritario",I43+K43,I43+J43+K43))) -> 16 | M43: =Q42 -> 5 | N43: =MIN(M43+H43,(M43+H43)*$B$15) -> 0.40753 | O43: =MAX(0,M43+H43-N43) -> 19.96897 | P43: =MIN(L43,O43) -> 16 | Q43: =MIN($B$10,MAX(0,O43-P43)) -> 3.96897 | R43: =MAX(0,O43-P43-$B$10) -> 0 | S43: =MAX(0,L43-P43) -> 0 | T43: =IF(P43>=L43*$B$16,"Satisfactorio","Falla") -> Satisfactorio | U43: =IF(AND(T42="Falla",T43="Satisfactorio"),1,0) -> 0 | V43: =IF(AND(T43="Falla",T42<>"Falla"),1,0) -> 0 | X43: 1999 | Y43: =SUMIF($B$25:$B$384,X43,$H$25:$H$384) -> 213.22462 | Z43: =SUMIF($B$25:$B$384,X43,$L$25:$L$384) -> 165 | AA43: =SUMIF($B$25:$B$384,X43,$P$25:$P$384) -> 157.69963 | AB43: =COUNTIFS($B$25:$B$384,X43,$T$25:$T$384,"Satisfactorio")/COUNTIF($B$25:$B$384,X43) -> 0.75
A44: 30164 | B44: 1982 | C44: Agosto | D44: 86.1 | E44: ='Hoja 4 - Cálculo'!$B$12 -> 250 | F44: ='Hoja 4 - Cálculo'!$B$13 -> 0.85 | G44: ='Hoja 4 - Cálculo'!$B$14 -> 0.9 | H44: =D44*E44*F44*G44/1000 -> 16.466625 | I44: 8 | J44: 6 | K44: 2 | L44: =IF($B$9="Uso único",I44,IF($B$9="Uso múltiple",AVERAGE($I$25:$I$384)+AVERAGE($J$25:$J$384)+AVERAGE($K$25:$K$384),IF($B$9="Uso prioritario",I44+K44,I44+J44+K44))) -> 16 | M44: =Q43 -> 3.96897 | N44: =MIN(M44+H44,(M44+H44)*$B$15) -> 0.4087119 | O44: =MAX(0,M44+H44-N44) -> 20.026883 | P44: =MIN(L44,O44) -> 16 | Q44: =MIN($B$10,MAX(0,O44-P44)) -> 4.0268831 | R44: =MAX(0,O44-P44-$B$10) -> 0 | S44: =MAX(0,L44-P44) -> 0 | T44: =IF(P44>=L44*$B$16,"Satisfactorio","Falla") -> Satisfactorio | U44: =IF(AND(T43="Falla",T44="Satisfactorio"),1,0) -> 0 | V44: =IF(AND(T44="Falla",T43<>"Falla"),1,0) -> 0 | X44: 2000 | Y44: =SUMIF($B$25:$B$384,X44,$H$25:$H$384) -> 238.39313 | Z44: =SUMIF($B$25:$B$384,X44,$L$25:$L$384) -> 165 | AA44: =SUMIF($B$25:$B$384,X44,$P$25:$P$384) -> 157.45748 | AB44: =COUNTIFS($B$25:$B$384,X44,$T$25:$T$384,"Satisfactorio")/COUNTIF($B$25:$B$384,X44) -> 0.75
A45: 30195 | B45: 1982 | C45: Septiembre | D45: 135.1 | E45: ='Hoja 4 - Cálculo'!$B$12 -> 250 | F45: ='Hoja 4 - Cálculo'!$B$13 -> 0.85 | G45: ='Hoja 4 - Cálculo'!$B$14 -> 0.9 | H45: =D45*E45*F45*G45/1000 -> 25.837875 | I45: 8 | J45: 1.5 | K45: 2 | L45: =IF($B$9="Uso único",I45,IF($B$9="Uso múltiple",AVERAGE($I$25:$I$384)+AVERAGE($J$25:$J$384)+AVERAGE($K$25:$K$384),IF($B$9="Uso prioritario",I45+K45,I45+J45+K45))) -> 11.5 | M45: =Q44 -> 4.0268831 | N45: =MIN(M45+H45,(M45+H45)*$B$15) -> 0.59729516 | O45: =MAX(0,M45+H45-N45) -> 29.267463 | P45: =MIN(L45,O45) -> 11.5 | Q45: =MIN($B$10,MAX(0,O45-P45)) -> 5 | R45: =MAX(0,O45-P45-$B$10) -> 12.767463 | S45: =MAX(0,L45-P45) -> 0 | T45: =IF(P45>=L45*$B$16,"Satisfactorio","Falla") -> Satisfactorio | U45: =IF(AND(T44="Falla",T45="Satisfactorio"),1,0) -> 0 | V45: =IF(AND(T45="Falla",T44<>"Falla"),1,0) -> 0 | X45: 2001 | Y45: =SUMIF($B$25:$B$384,X45,$H$25:$H$384) -> 265.93313 | Z45: =SUMIF($B$25:$B$384,X45,$L$25:$L$384) -> 165 | AA45: =SUMIF($B$25:$B$384,X45,$P$25:$P$384) -> 164.24952 | AB45: =COUNTIFS($B$25:$B$384,X45,$T$25:$T$384,"Satisfactorio")/COUNTIF($B$25:$B$384,X45) -> 0.83333333
A46: 30225 | B46: 1982 | C46: Octubre | D46: 175 | E46: ='Hoja 4 - Cálculo'!$B$12 -> 250 | F46: ='Hoja 4 - Cálculo'!$B$13 -> 0.85 | G46: ='Hoja 4 - Cálculo'!$B$14 -> 0.9 | H46: =D46*E46*F46*G46/1000 -> 33.46875 | I46: 8 | J46: 1.5 | K46: 2 | L46: =IF($B$9="Uso único",I46,IF($B$9="Uso múltiple",AVERAGE($I$25:$I$384)+AVERAGE($J$25:$J$384)+AVERAGE($K$25:$K$384),IF($B$9="Uso prioritario",I46+K46,I46+J46+K46))) -> 11.5 | M46: =Q45 -> 5 | N46: =MIN(M46+H46,(M46+H46)*$B$15) -> 0.769375 | O46: =MAX(0,M46+H46-N46) -> 37.699375 | P46: =MIN(L46,O46) -> 11.5 | Q46: =MIN($B$10,MAX(0,O46-P46)) -> 5 | R46: =MAX(0,O46-P46-$B$10) -> 21.199375 | S46: =MAX(0,L46-P46) -> 0 | T46: =IF(P46>=L46*$B$16,"Satisfactorio","Falla") -> Satisfactorio | U46: =IF(AND(T45="Falla",T46="Satisfactorio"),1,0) -> 0 | V46: =IF(AND(T46="Falla",T45<>"Falla"),1,0) -> 0 | X46: 2002 | Y46: =SUMIF($B$25:$B$384,X46,$H$25:$H$384) -> 260.82675 | Z46: =SUMIF($B$25:$B$384,X46,$L$25:$L$384) -> 165 | AA46: =SUMIF($B$25:$B$384,X46,$P$25:$P$384) -> 165 | AB46: =COUNTIFS($B$25:$B$384,X46,$T$25:$T$384,"Satisfactorio")/COUNTIF($B$25:$B$384,X46) -> 1
A47: 30256 | B47: 1982 | C47: Noviembre | D47: 144.2 | E47: ='Hoja 4 - Cálculo'!$B$12 -> 250 | F47: ='Hoja 4 - Cálculo'!$B$13 -> 0.85 | G47: ='Hoja 4 - Cálculo'!$B$14 -> 0.9 | H47: =D47*E47*F47*G47/1000 -> 27.57825 | I47: 8 | J47: 1.5 | K47: 2 | L47: =IF($B$9="Uso único",I47,IF($B$9="Uso múltiple",AVERAGE($I$25:$I$384)+AVERAGE($J$25:$J$384)+AVERAGE($K$25:$K$384),IF($B$9="Uso prioritario",I47+K47,I47+J47+K47))) -> 11.5 | M47: =Q46 -> 5 | N47: =MIN(M47+H47,(M47+H47)*$B$15) -> 0.651565 | O47: =MAX(0,M47+H47-N47) -> 31.926685 | P47: =MIN(L47,O47) -> 11.5 | Q47: =MIN($B$10,MAX(0,O47-P47)) -> 5 | R47: =MAX(0,O47-P47-$B$10) -> 15.426685 | S47: =MAX(0,L47-P47) -> 0 | T47: =IF(P47>=L47*$B$16,"Satisfactorio","Falla") -> Satisfactorio | U47: =IF(AND(T46="Falla",T47="Satisfactorio"),1,0) -> 0 | V47: =IF(AND(T47="Falla",T46<>"Falla"),1,0) -> 0 | X47: 2003 | Y47: =SUMIF($B$25:$B$384,X47,$H$25:$H$384) -> 229.06012 | Z47: =SUMIF($B$25:$B$384,X47,$L$25:$L$384) -> 165 | AA47: =SUMIF($B$25:$B$384,X47,$P$25:$P$384) -> 162.09952 | AB47: =COUNTIFS($B$25:$B$384,X47,$T$25:$T$384,"Satisfactorio")/COUNTIF($B$25:$B$384,X47) -> 0.83333333
A48: 30286 | B48: 1982 | C48: Diciembre | D48: 85 | E48: ='Hoja 4 - Cálculo'!$B$12 -> 250 | F48: ='Hoja 4 - Cálculo'!$B$13 -> 0.85 | G48: ='Hoja 4 - Cálculo'!$B$14 -> 0.9 | H48: =D48*E48*F48*G48/1000 -> 16.25625 | I48: 8 | J48: 6 | K48: 2 | L48: =IF($B$9="Uso único",I48,IF($B$9="Uso múltiple",AVERAGE($I$25:$I$384)+AVERAGE($J$25:$J$384)+AVERAGE($K$25:$K$384),IF($B$9="Uso prioritario",I48+K48,I48+J48+K48))) -> 16 | M48: =Q47 -> 5 | N48: =MIN(M48+H48,(M48+H48)*$B$15) -> 0.425125 | O48: =MAX(0,M48+H48-N48) -> 20.831125 | P48: =MIN(L48,O48) -> 16 | Q48: =MIN($B$10,MAX(0,O48-P48)) -> 4.831125 | R48: =MAX(0,O48-P48-$B$10) -> 0 | S48: =MAX(0,L48-P48) -> 0 | T48: =IF(P48>=L48*$B$16,"Satisfactorio","Falla") -> Satisfactorio | U48: =IF(AND(T47="Falla",T48="Satisfactorio"),1,0) -> 0 | V48: =IF(AND(T48="Falla",T47<>"Falla"),1,0) -> 0 | X48: 2004 | Y48: =SUMIF($B$25:$B$384,X48,$H$25:$H$384) -> 217.27912 | Z48: =SUMIF($B$25:$B$384,X48,$L$25:$L$384) -> 165 | AA48: =SUMIF($B$25:$B$384,X48,$P$25:$P$384) -> 156.08553 | AB48: =COUNTIFS($B$25:$B$384,X48,$T$25:$T$384,"Satisfactorio")/COUNTIF($B$25:$B$384,X48) -> 0.75
A49: 30317 | B49: 1983 | C49: Enero | D49: 66.8 | E49: ='Hoja 4 - Cálculo'!$B$12 -> 250 | F49: ='Hoja 4 - Cálculo'!$B$13 -> 0.85 | G49: ='Hoja 4 - Cálculo'!$B$14 -> 0.9 | H49: =D49*E49*F49*G49/1000 -> 12.7755 | I49: 8 | J49: 6 | K49: 2 | L49: =IF($B$9="Uso único",I49,IF($B$9="Uso múltiple",AVERAGE($I$25:$I$384)+AVERAGE($J$25:$J$384)+AVERAGE($K$25:$K$384),IF($B$9="Uso prioritario",I49+K49,I49+J49+K49))) -> 16 | M49: =Q48 -> 4.831125 | N49: =MIN(M49+H49,(M49+H49)*$B$15) -> 0.3521325 | O49: =MAX(0,M49+H49-N49) -> 17.254493 | P49: =MIN(L49,O49) -> 16 | Q49: =MIN($B$10,MAX(0,O49-P49)) -> 1.2544925 | R49: =MAX(0,O49-P49-$B$10) -> 0 | S49: =MAX(0,L49-P49) -> 0 | T49: =IF(P49>=L49*$B$16,"Satisfactorio","Falla") -> Satisfactorio | U49: =IF(AND(T48="Falla",T49="Satisfactorio"),1,0) -> 0 | V49: =IF(AND(T49="Falla",T48<>"Falla"),1,0) -> 0 | X49: 2005 | Y49: =SUMIF($B$25:$B$384,X49,$H$25:$H$384) -> 243.9585 | Z49: =SUMIF($B$25:$B$384,X49,$L$25:$L$384) -> 165 | AA49: =SUMIF($B$25:$B$384,X49,$P$25:$P$384) -> 161.07266 | AB49: =COUNTIFS($B$25:$B$384,X49,$T$25:$T$384,"Satisfactorio")/COUNTIF($B$25:$B$384,X49) -> 0.83333333
...

Sheet Curvas SRY
A1: CF2 · CURVAS SRY Y COMPARACIÓN DE ALTERNATIVAS
A2: Evalúe un rango de capacidades y tres niveles de rendimiento. La simulación aplica el mismo balance temporal de la Hoja 4; las celdas azules son decisiones de diseño y los resultados se actualizan automáticamente.
A4: LEYENDA | B4: Entrada | C4: Fórmula | D4: Alerta | E4: Ejemplo | F4: Unidades en encabezado
A6: CONTROLES DE LA SIMULACIÓN SRY | H6: MATRIZ PARA LA CURVA SRY
A7: Capacidad candidata (m³) | B7: Valor | D7: Rendimiento objetivo | E7: Factor | H7: Capacidad (m³) | I7: R bajo | J7: R base | K7: R alto | L7: Conclusión
A8: C1 | B8: 1 | D8: Bajo | E8: 0.75 | H8: =B8 -> 1 | I8: =COUNTIFS('Soporte SRY'!$A$4:$A$2163,"SRY-1-1",'Soporte SRY'!$Q$4:$Q$2163,"Satisfactorio")/$E$13 -> 0.98333333 | J8: =COUNTIFS('Soporte SRY'!$A$4:$A$2163,"SRY-1-2",'Soporte SRY'!$Q$4:$Q$2163,"Satisfactorio")/$E$13 -> 0.64166667 | K8: =COUNTIFS('Soporte SRY'!$A$4:$A$2163,"SRY-1-3",'Soporte SRY'!$Q$4:$Q$2163,"Satisfactorio")/$E$13 -> 0.55 | L8: =IF(K8>=$E$12,"Cumple incluso con rendimiento alto",IF(J8>=$E$12,"Cumple con rendimiento base",IF(I8>=$E$12,"Cumple solo con rendimiento bajo","No cumple la meta"))) -> Cumple solo con rendimiento bajo
A9: C2 | B9: 2 | D9: Base | E9: 1 | H9: =B9 -> 2 | I9: =COUNTIFS('Soporte SRY'!$A$4:$A$2163,"SRY-2-1",'Soporte SRY'!$Q$4:$Q$2163,"Satisfactorio")/$E$13 -> 1 | J9: =COUNTIFS('Soporte SRY'!$A$4:$A$2163,"SRY-2-2",'Soporte SRY'!$Q$4:$Q$2163,"Satisfactorio")/$E$13 -> 0.675 | K9: =COUNTIFS('Soporte SRY'!$A$4:$A$2163,"SRY-2-3",'Soporte SRY'!$Q$4:$Q$2163,"Satisfactorio")/$E$13 -> 0.55 | L9: =IF(K9>=$E$12,"Cumple incluso con rendimiento alto",IF(J9>=$E$12,"Cumple con rendimiento base",IF(I9>=$E$12,"Cumple solo con rendimiento bajo","No cumple la meta"))) -> Cumple solo con rendimiento bajo
A10: C3 | B10: 3 | D10: Alto | E10: 1.25 | H10: =B10 -> 3 | I10: =COUNTIFS('Soporte SRY'!$A$4:$A$2163,"SRY-3-1",'Soporte SRY'!$Q$4:$Q$2163,"Satisfactorio")/$E$13 -> 1 | J10: =COUNTIFS('Soporte SRY'!$A$4:$A$2163,"SRY-3-2",'Soporte SRY'!$Q$4:$Q$2163,"Satisfactorio")/$E$13 -> 0.725 | K10: =COUNTIFS('Soporte SRY'!$A$4:$A$2163,"SRY-3-3",'Soporte SRY'!$Q$4:$Q$2163,"Satisfactorio")/$E$13 -> 0.55 | L10: =IF(K10>=$E$12,"Cumple incluso con rendimiento alto",IF(J10>=$E$12,"Cumple con rendimiento base",IF(I10>=$E$12,"Cumple solo con rendimiento bajo","No cumple la meta"))) -> Cumple solo con rendimiento bajo
A11: C4 | B11: 5 | D11: Capacidad para comparar usos (m³) | E11: 5 | H11: =B11 -> 5 | I11: =COUNTIFS('Soporte SRY'!$A$4:$A$2163,"SRY-4-1",'Soporte SRY'!$Q$4:$Q$2163,"Satisfactorio")/$E$13 -> 1 | J11: =COUNTIFS('Soporte SRY'!$A$4:$A$2163,"SRY-4-2",'Soporte SRY'!$Q$4:$Q$2163,"Satisfactorio")/$E$13 -> 0.85 | K11: =COUNTIFS('Soporte SRY'!$A$4:$A$2163,"SRY-4-3",'Soporte SRY'!$Q$4:$Q$2163,"Satisfactorio")/$E$13 -> 0.58333333 | L11: =IF(K11>=$E$12,"Cumple incluso con rendimiento alto",IF(J11>=$E$12,"Cumple con rendimiento base",IF(I11>=$E$12,"Cumple solo con rendimiento bajo","No cumple la meta"))) -> Cumple solo con rendimiento bajo
A12: C5 | B12: 10 | D12: Fiabilidad objetivo | E12: 0.9 | H12: =B12 -> 10 | I12: =COUNTIFS('Soporte SRY'!$A$4:$A$2163,"SRY-5-1",'Soporte SRY'!$Q$4:$Q$2163,"Satisfactorio")/$E$13 -> 1 | J12: =COUNTIFS('Soporte SRY'!$A$4:$A$2163,"SRY-5-2",'Soporte SRY'!$Q$4:$Q$2163,"Satisfactorio")/$E$13 -> 0.975 | K12: =COUNTIFS('Soporte SRY'!$A$4:$A$2163,"SRY-5-3",'Soporte SRY'!$Q$4:$Q$2163,"Satisfactorio")/$E$13 -> 0.725 | L12: =IF(K12>=$E$12,"Cumple incluso con rendimiento alto",IF(J12>=$E$12,"Cumple con rendimiento base",IF(I12>=$E$12,"Cumple solo con rendimiento bajo","No cumple la meta"))) -> Cumple con rendimiento base
A13: C6 | B13: 15 | D13: Periodos en curvas SRY | E13: 120 | H13: =B13 -> 15 | I13: =COUNTIFS('Soporte SRY'!$A$4:$A$2163,"SRY-6-1",'Soporte SRY'!$Q$4:$Q$2163,"Satisfactorio")/$E$13 -> 1 | J13: =COUNTIFS('Soporte SRY'!$A$4:$A$2163,"SRY-6-2",'Soporte SRY'!$Q$4:$Q$2163,"Satisfactorio")/$E$13 -> 0.98333333 | K13: =COUNTIFS('Soporte SRY'!$A$4:$A$2163,"SRY-6-3",'Soporte SRY'!$Q$4:$Q$2163,"Satisfactorio")/$E$13 -> 0.84166667 | L13: =IF(K13>=$E$12,"Cumple incluso con rendimiento alto",IF(J13>=$E$12,"Cumple con rendimiento base",IF(I13>=$E$12,"Cumple solo con rendimiento bajo","No cumple la meta"))) -> Cumple con rendimiento base
A14: Configuración evaluada | B14: Uso variable
A16: Curva SRY: para cada capacidad se repite el balance, se identifican fallas y se calcula R = 1 − Nf/N. La comparación didáctica usa 120 meses consecutivos; para un estudio técnico debe ampliarse a toda la serie validada. Los tres factores representan niveles de demanda/rendimiento.
A21: RESUMEN DETALLADO DE 18 ALTERNATIVAS
A22: ID | B22: Capacidad (m³) | C22: Factor demanda | D22: Fiabilidad | E22: Déficit total (m³) | F22: Vulnerabilidad media (m³/evento) | G22: Duración media (periodos) | H22: Resiliencia | I22: Rebose (m³) | K22: COMPARACIÓN DE CONFIGURACIONES
A23: ="SRY-1-1" -> SRY-1-1 | B23: =$B$8 -> 1 | C23: =$E$8 -> 0.75 | D23: =COUNTIFS('Soporte SRY'!$A$4:$A$2163,A23,'Soporte SRY'!$Q$4:$Q$2163,"Satisfactorio")/$E$13 -> 0.98333333 | E23: =SUMIF('Soporte SRY'!$A$4:$A$2163,A23,'Soporte SRY'!$P$4:$P$2163) -> 0.786005 | F23: =IF(SUMIF('Soporte SRY'!$A$4:$A$2163,A23,'Soporte SRY'!$S$4:$S$2163)=0,0,E23/SUMIF('Soporte SRY'!$A$4:$A$2163,A23,'Soporte SRY'!$S$4:$S$2163)) -> 0.3930025 | G23: =IF(SUMIF('Soporte SRY'!$A$4:$A$2163,A23,'Soporte SRY'!$S$4:$S$2163)=0,0,COUNTIFS('Soporte SRY'!$A$4:$A$2163,A23,'Soporte SRY'!$Q$4:$Q$2163,"Falla")/SUMIF('Soporte SRY'!$A$4:$A$2163,A23,'Soporte SRY'!$S$4:$S$2163)) -> 1 | H23: =IF(COUNTIFS('Soporte SRY'!$A$4:$A$2163,A23,'Soporte SRY'!$Q$4:$Q$2163,"Falla")=0,1,SUMIF('Soporte SRY'!$A$4:$A$2163,A23,'Soporte SRY'!$R$4:$R$2163)/COUNTIFS('Soporte SRY'!$A$4:$A$2163,A23,'Soporte SRY'!$Q$4:$Q$2163,"Falla")) -> 1 | I23: =SUMIF('Soporte SRY'!$A$4:$A$2163,A23,'Soporte SRY'!$O$4:$O$2163) -> 1131.2662 | K23: Configuración | L23: Fiabilidad | M23: Déficit (m³) | N23: Rebose (m³) | O23: Lectura
A24: ="SRY-1-2" -> SRY-1-2 | B24: =$B$8 -> 1 | C24: =$E$9 -> 1 | D24: =COUNTIFS('Soporte SRY'!$A$4:$A$2163,A24,'Soporte SRY'!$Q$4:$Q$2163,"Satisfactorio")/$E$13 -> 0.64166667 | E24: =SUMIF('Soporte SRY'!$A$4:$A$2163,A24,'Soporte SRY'!$P$4:$P$2163) -> 99.332265 | F24: =IF(SUMIF('Soporte SRY'!$A$4:$A$2163,A24,'Soporte SRY'!$S$4:$S$2163)=0,0,E24/SUMIF('Soporte SRY'!$A$4:$A$2163,A24,'Soporte SRY'!$S$4:$S$2163)) -> 4.9666132 | G24: =IF(SUMIF('Soporte SRY'!$A$4:$A$2163,A24,'Soporte SRY'!$S$4:$S$2163)=0,0,COUNTIFS('Soporte SRY'!$A$4:$A$2163,A24,'Soporte SRY'!$Q$4:$Q$2163,"Falla")/SUMIF('Soporte SRY'!$A$4:$A$2163,A24,'Soporte SRY'!$S$4:$S$2163)) -> 2.15 | H24: =IF(COUNTIFS('Soporte SRY'!$A$4:$A$2163,A24,'Soporte SRY'!$Q$4:$Q$2163,"Falla")=0,1,SUMIF('Soporte SRY'!$A$4:$A$2163,A24,'Soporte SRY'!$R$4:$R$2163)/COUNTIFS('Soporte SRY'!$A$4:$A$2163,A24,'Soporte SRY'!$Q$4:$Q$2163,"Falla")) -> 0.44186047 | I24: =SUMIF('Soporte SRY'!$A$4:$A$2163,A24,'Soporte SRY'!$O$4:$O$2163) -> 819.12267 | K24: Uso único | L24: =COUNTIFS('Soporte SRY'!$A$2164:$A$2643,"CFG-1",'Soporte SRY'!$Q$2164:$Q$2643,"Satisfactorio")/$E$13 -> 1 | M24: =SUMIF('Soporte SRY'!$A$2164:$A$2643,"CFG-1",'Soporte SRY'!$P$2164:$P$2643) -> 0 | N24: =SUMIF('Soporte SRY'!$A$2164:$A$2643,"CFG-1",'Soporte SRY'!$O$2164:$O$2643) -> 1394.3717 | O24: =IF(L24>=$E$12,"Cumple la meta","Requiere ajuste") -> Cumple la meta
A25: ="SRY-1-3" -> SRY-1-3 | B25: =$B$8 -> 1 | C25: =$E$10 -> 1.25 | D25: =COUNTIFS('Soporte SRY'!$A$4:$A$2163,A25,'Soporte SRY'!$Q$4:$Q$2163,"Satisfactorio")/$E$13 -> 0.55 | E25: =SUMIF('Soporte SRY'!$A$4:$A$2163,A25,'Soporte SRY'!$P$4:$P$2163) -> 302.46753 | F25: =IF(SUMIF('Soporte SRY'!$A$4:$A$2163,A25,'Soporte SRY'!$S$4:$S$2163)=0,0,E25/SUMIF('Soporte SRY'!$A$4:$A$2163,A25,'Soporte SRY'!$S$4:$S$2163)) -> 14.403216 | G25: =IF(SUMIF('Soporte SRY'!$A$4:$A$2163,A25,'Soporte SRY'!$S$4:$S$2163)=0,0,COUNTIFS('Soporte SRY'!$A$4:$A$2163,A25,'Soporte SRY'!$Q$4:$Q$2163,"Falla")/SUMIF('Soporte SRY'!$A$4:$A$2163,A25,'Soporte SRY'!$S$4:$S$2163)) -> 2.5714286 | H25: =IF(COUNTIFS('Soporte SRY'!$A$4:$A$2163,A25,'Soporte SRY'!$Q$4:$Q$2163,"Falla")=0,1,SUMIF('Soporte SRY'!$A$4:$A$2163,A25,'Soporte SRY'!$R$4:$R$2163)/COUNTIFS('Soporte SRY'!$A$4:$A$2163,A25,'Soporte SRY'!$Q$4:$Q$2163,"Falla")) -> 0.37037037 | I25: =SUMIF('Soporte SRY'!$A$4:$A$2163,A25,'Soporte SRY'!$O$4:$O$2163) -> 609.93476 | K25: Uso múltiple | L25: =COUNTIFS('Soporte SRY'!$A$2164:$A$2643,"CFG-2",'Soporte SRY'!$Q$2164:$Q$2643,"Satisfactorio")/$E$13 -> 0.99166667 | M25: =SUMIF('Soporte SRY'!$A$2164:$A$2643,"CFG-2",'Soporte SRY'!$P$2164:$P$2643) -> 1.15504 | N25: =SUMIF('Soporte SRY'!$A$2164:$A$2643,"CFG-2",'Soporte SRY'!$O$2164:$O$2643) -> 707.2006 | O25: =IF(L25>=$E$12,"Cumple la meta","Requiere ajuste") -> Cumple la meta
A26: ="SRY-2-1" -> SRY-2-1 | B26: =$B$9 -> 2 | C26: =$E$8 -> 0.75 | D26: =COUNTIFS('Soporte SRY'!$A$4:$A$2163,A26,'Soporte SRY'!$Q$4:$Q$2163,"Satisfactorio")/$E$13 -> 1 | E26: =SUMIF('Soporte SRY'!$A$4:$A$2163,A26,'Soporte SRY'!$P$4:$P$2163) -> 0 | F26: =IF(SUMIF('Soporte SRY'!$A$4:$A$2163,A26,'Soporte SRY'!$S$4:$S$2163)=0,0,E26/SUMIF('Soporte SRY'!$A$4:$A$2163,A26,'Soporte SRY'!$S$4:$S$2163)) -> 0 | G26: =IF(SUMIF('Soporte SRY'!$A$4:$A$2163,A26,'Soporte SRY'!$S$4:$S$2163)=0,0,COUNTIFS('Soporte SRY'!$A$4:$A$2163,A26,'Soporte SRY'!$Q$4:$Q$2163,"Falla")/SUMIF('Soporte SRY'!$A$4:$A$2163,A26,'Soporte SRY'!$S$4:$S$2163)) -> 0 | H26: =IF(COUNTIFS('Soporte SRY'!$A$4:$A$2163,A26,'Soporte SRY'!$Q$4:$Q$2163,"Falla")=0,1,SUMIF('Soporte SRY'!$A$4:$A$2163,A26,'Soporte SRY'!$R$4:$R$2163)/COUNTIFS('Soporte SRY'!$A$4:$A$2163,A26,'Soporte SRY'!$Q$4:$Q$2163,"Falla")) -> 1 | I26: =SUMIF('Soporte SRY'!$A$4:$A$2163,A26,'Soporte SRY'!$O$4:$O$2163) -> 1127.1534 | K26: Uso prioritario | L26: =COUNTIFS('Soporte SRY'!$A$2164:$A$2643,"CFG-3",'Soporte SRY'!$Q$2164:$Q$2643,"Satisfactorio")/$E$13 -> 1 | M26: =SUMIF('Soporte SRY'!$A$2164:$A$2643,"CFG-3",'Soporte SRY'!$P$2164:$P$2643) -> 0 | N26: =SUMIF('Soporte SRY'!$A$2164:$A$2643,"CFG-3",'Soporte SRY'!$O$2164:$O$2643) -> 1154.4117 | O26: =IF(L26>=$E$12,"Cumple la meta","Requiere ajuste") -> Cumple la meta
A27: ="SRY-2-2" -> SRY-2-2 | B27: =$B$9 -> 2 | C27: =$E$9 -> 1 | D27: =COUNTIFS('Soporte SRY'!$A$4:$A$2163,A27,'Soporte SRY'!$Q$4:$Q$2163,"Satisfactorio")/$E$13 -> 0.675 | E27: =SUMIF('Soporte SRY'!$A$4:$A$2163,A27,'Soporte SRY'!$P$4:$P$2163) -> 80.823127 | F27: =IF(SUMIF('Soporte SRY'!$A$4:$A$2163,A27,'Soporte SRY'!$S$4:$S$2163)=0,0,E27/SUMIF('Soporte SRY'!$A$4:$A$2163,A27,'Soporte SRY'!$S$4:$S$2163)) -> 4.0411564 | G27: =IF(SUMIF('Soporte SRY'!$A$4:$A$2163,A27,'Soporte SRY'!$S$4:$S$2163)=0,0,COUNTIFS('Soporte SRY'!$A$4:$A$2163,A27,'Soporte SRY'!$Q$4:$Q$2163,"Falla")/SUMIF('Soporte SRY'!$A$4:$A$2163,A27,'Soporte SRY'!$S$4:$S$2163)) -> 1.95 | H27: =IF(COUNTIFS('Soporte SRY'!$A$4:$A$2163,A27,'Soporte SRY'!$Q$4:$Q$2163,"Falla")=0,1,SUMIF('Soporte SRY'!$A$4:$A$2163,A27,'Soporte SRY'!$R$4:$R$2163)/COUNTIFS('Soporte SRY'!$A$4:$A$2163,A27,'Soporte SRY'!$Q$4:$Q$2163,"Falla")) -> 0.48717949 | I27: =SUMIF('Soporte SRY'!$A$4:$A$2163,A27,'Soporte SRY'!$O$4:$O$2163) -> 799.04386 | K27: Uso variable | L27: =COUNTIFS('Soporte SRY'!$A$2164:$A$2643,"CFG-4",'Soporte SRY'!$Q$2164:$Q$2643,"Satisfactorio")/$E$13 -> 0.85 | M27: =SUMIF('Soporte SRY'!$A$2164:$A$2643,"CFG-4",'Soporte SRY'!$P$2164:$P$2643) -> 35.255768 | N27: =SUMIF('Soporte SRY'!$A$2164:$A$2643,"CFG-4",'Soporte SRY'!$O$2164:$O$2643) -> 745.86763 | O27: =IF(L27>=$E$12,"Cumple la meta","Requiere ajuste") -> Requiere ajuste
A28: ="SRY-2-3" -> SRY-2-3 | B28: =$B$9 -> 2 | C28: =$E$10 -> 1.25 | D28: =COUNTIFS('Soporte SRY'!$A$4:$A$2163,A28,'Soporte SRY'!$Q$4:$Q$2163,"Satisfactorio")/$E$13 -> 0.55 | E28: =SUMIF('Soporte SRY'!$A$4:$A$2163,A28,'Soporte SRY'!$P$4:$P$2163) -> 282.90673 | F28: =IF(SUMIF('Soporte SRY'!$A$4:$A$2163,A28,'Soporte SRY'!$S$4:$S$2163)=0,0,E28/SUMIF('Soporte SRY'!$A$4:$A$2163,A28,'Soporte SRY'!$S$4:$S$2163)) -> 13.471749 | G28: =IF(SUMIF('Soporte SRY'!$A$4:$A$2163,A28,'Soporte SRY'!$S$4:$S$2163)=0,0,COUNTIFS('Soporte SRY'!$A$4:$A$2163,A28,'Soporte SRY'!$Q$4:$Q$2163,"Falla")/SUMIF('Soporte SRY'!$A$4:$A$2163,A28,'Soporte SRY'!$S$4:$S$2163)) -> 2.5714286 | H28: =IF(COUNTIFS('Soporte SRY'!$A$4:$A$2163,A28,'Soporte SRY'!$Q$4:$Q$2163,"Falla")=0,1,SUMIF('Soporte SRY'!$A$4:$A$2163,A28,'Soporte SRY'!$R$4:$R$2163)/COUNTIFS('Soporte SRY'!$A$4:$A$2163,A28,'Soporte SRY'!$Q$4:$Q$2163,"Falla")) -> 0.37037037 | I28: =SUMIF('Soporte SRY'!$A$4:$A$2163,A28,'Soporte SRY'!$O$4:$O$2163) -> 589.10915
A29: ="SRY-3-1" -> SRY-3-1 | B29: =$B$10 -> 3 | C29: =$E$8 -> 0.75 | D29: =COUNTIFS('Soporte SRY'!$A$4:$A$2163,A29,'Soporte SRY'!$Q$4:$Q$2163,"Satisfactorio")/$E$13 -> 1 | E29: =SUMIF('Soporte SRY'!$A$4:$A$2163,A29,'Soporte SRY'!$P$4:$P$2163) -> 0 | F29: =IF(SUMIF('Soporte SRY'!$A$4:$A$2163,A29,'Soporte SRY'!$S$4:$S$2163)=0,0,E29/SUMIF('Soporte SRY'!$A$4:$A$2163,A29,'Soporte SRY'!$S$4:$S$2163)) -> 0 | G29: =IF(SUMIF('Soporte SRY'!$A$4:$A$2163,A29,'Soporte SRY'!$S$4:$S$2163)=0,0,COUNTIFS('Soporte SRY'!$A$4:$A$2163,A29,'Soporte SRY'!$Q$4:$Q$2163,"Falla")/SUMIF('Soporte SRY'!$A$4:$A$2163,A29,'Soporte SRY'!$S$4:$S$2163)) -> 0 | H29: =IF(COUNTIFS('Soporte SRY'!$A$4:$A$2163,A29,'Soporte SRY'!$Q$4:$Q$2163,"Falla")=0,1,SUMIF('Soporte SRY'!$A$4:$A$2163,A29,'Soporte SRY'!$R$4:$R$2163)/COUNTIFS('Soporte SRY'!$A$4:$A$2163,A29,'Soporte SRY'!$Q$4:$Q$2163,"Falla")) -> 1 | I29: =SUMIF('Soporte SRY'!$A$4:$A$2163,A29,'Soporte SRY'!$O$4:$O$2163) -> 1123.801
A30: ="SRY-3-2" -> SRY-3-2 | B30: =$B$10 -> 3 | C30: =$E$9 -> 1 | D30: =COUNTIFS('Soporte SRY'!$A$4:$A$2163,A30,'Soporte SRY'!$Q$4:$Q$2163,"Satisfactorio")/$E$13 -> 0.725 | E30: =SUMIF('Soporte SRY'!$A$4:$A$2163,A30,'Soporte SRY'!$P$4:$P$2163) -> 63.554431 | F30: =IF(SUMIF('Soporte SRY'!$A$4:$A$2163,A30,'Soporte SRY'!$S$4:$S$2163)=0,0,E30/SUMIF('Soporte SRY'!$A$4:$A$2163,A30,'Soporte SRY'!$S$4:$S$2163)) -> 3.5308017 | G30: =IF(SUMIF('Soporte SRY'!$A$4:$A$2163,A30,'Soporte SRY'!$S$4:$S$2163)=0,0,COUNTIFS('Soporte SRY'!$A$4:$A$2163,A30,'Soporte SRY'!$Q$4:$Q$2163,"Falla")/SUMIF('Soporte SRY'!$A$4:$A$2163,A30,'Soporte SRY'!$S$4:$S$2163)) -> 1.8333333 | H30: =IF(COUNTIFS('Soporte SRY'!$A$4:$A$2163,A30,'Soporte SRY'!$Q$4:$Q$2163,"Falla")=0,1,SUMIF('Soporte SRY'!$A$4:$A$2163,A30,'Soporte SRY'!$R$4:$R$2163)/COUNTIFS('Soporte SRY'!$A$4:$A$2163,A30,'Soporte SRY'!$Q$4:$Q$2163,"Falla")) -> 0.54545455 | I30: =SUMIF('Soporte SRY'!$A$4:$A$2163,A30,'Soporte SRY'!$O$4:$O$2163) -> 779.71217
A31: ="SRY-3-3" -> SRY-3-3 | B31: =$B$10 -> 3 | C31: =$E$10 -> 1.25 | D31: =COUNTIFS('Soporte SRY'!$A$4:$A$2163,A31,'Soporte SRY'!$Q$4:$Q$2163,"Satisfactorio")/$E$13 -> 0.55 | E31: =SUMIF('Soporte SRY'!$A$4:$A$2163,A31,'Soporte SRY'!$P$4:$P$2163) -> 263.34593 | F31: =IF(SUMIF('Soporte SRY'!$A$4:$A$2163,A31,'Soporte SRY'!$S$4:$S$2163)=0,0,E31/SUMIF('Soporte SRY'!$A$4:$A$2163,A31,'Soporte SRY'!$S$4:$S$2163)) -> 12.540283 | G31: =IF(SUMIF('Soporte SRY'!$A$4:$A$2163,A31,'Soporte SRY'!$S$4:$S$2163)=0,0,COUNTIFS('Soporte SRY'!$A$4:$A$2163,A31,'Soporte SRY'!$Q$4:$Q$2163,"Falla")/SUMIF('Soporte SRY'!$A$4:$A$2163,A31,'Soporte SRY'!$S$4:$S$2163)) -> 2.5714286 | H31: =IF(COUNTIFS('Soporte SRY'!$A$4:$A$2163,A31,'Soporte SRY'!$Q$4:$Q$2163,"Falla")=0,1,SUMIF('Soporte SRY'!$A$4:$A$2163,A31,'Soporte SRY'!$R$4:$R$2163)/COUNTIFS('Soporte SRY'!$A$4:$A$2163,A31,'Soporte SRY'!$Q$4:$Q$2163,"Falla")) -> 0.37037037 | I31: =SUMIF('Soporte SRY'!$A$4:$A$2163,A31,'Soporte SRY'!$O$4:$O$2163) -> 568.34233
A32: ="SRY-4-1" -> SRY-4-1 | B32: =$B$11 -> 5 | C32: =$E$8 -> 0.75 | D32: =COUNTIFS('Soporte SRY'!$A$4:$A$2163,A32,'Soporte SRY'!$Q$4:$Q$2163,"Satisfactorio")/$E$13 -> 1 | E32: =SUMIF('Soporte SRY'!$A$4:$A$2163,A32,'Soporte SRY'!$P$4:$P$2163) -> 0 | F32: =IF(SUMIF('Soporte SRY'!$A$4:$A$2163,A32,'Soporte SRY'!$S$4:$S$2163)=0,0,E32/SUMIF('Soporte SRY'!$A$4:$A$2163,A32,'Soporte SRY'!$S$4:$S$2163)) -> 0 | G32: =IF(SUMIF('Soporte SRY'!$A$4:$A$2163,A32,'Soporte SRY'!$S$4:$S$2163)=0,0,COUNTIFS('Soporte SRY'!$A$4:$A$2163,A32,'Soporte SRY'!$Q$4:$Q$2163,"Falla")/SUMIF('Soporte SRY'!$A$4:$A$2163,A32,'Soporte SRY'!$S$4:$S$2163)) -> 0 | H32: =IF(COUNTIFS('Soporte SRY'!$A$4:$A$2163,A32,'Soporte SRY'!$Q$4:$Q$2163,"Falla")=0,1,SUMIF('Soporte SRY'!$A$4:$A$2163,A32,'Soporte SRY'!$R$4:$R$2163)/COUNTIFS('Soporte SRY'!$A$4:$A$2163,A32,'Soporte SRY'!$Q$4:$Q$2163,"Falla")) -> 1 | I32: =SUMIF('Soporte SRY'!$A$4:$A$2163,A32,'Soporte SRY'!$O$4:$O$2163) -> 1117.1329
A33: ="SRY-4-2" -> SRY-4-2 | B33: =$B$11 -> 5 | C33: =$E$9 -> 1 | D33: =COUNTIFS('Soporte SRY'!$A$4:$A$2163,A33,'Soporte SRY'!$Q$4:$Q$2163,"Satisfactorio")/$E$13 -> 0.85 | E33: =SUMIF('Soporte SRY'!$A$4:$A$2163,A33,'Soporte SRY'!$P$4:$P$2163) -> 35.255768 | F33: =IF(SUMIF('Soporte SRY'!$A$4:$A$2163,A33,'Soporte SRY'!$S$4:$S$2163)=0,0,E33/SUMIF('Soporte SRY'!$A$4:$A$2163,A33,'Soporte SRY'!$S$4:$S$2163)) -> 2.7119822 | G33: =IF(SUMIF('Soporte SRY'!$A$4:$A$2163,A33,'Soporte SRY'!$S$4:$S$2163)=0,0,COUNTIFS('Soporte SRY'!$A$4:$A$2163,A33,'Soporte SRY'!$Q$4:$Q$2163,"Falla")/SUMIF('Soporte SRY'!$A$4:$A$2163,A33,'Soporte SRY'!$S$4:$S$2163)) -> 1.3846154 | H33: =IF(COUNTIFS('Soporte SRY'!$A$4:$A$2163,A33,'Soporte SRY'!$Q$4:$Q$2163,"Falla")=0,1,SUMIF('Soporte SRY'!$A$4:$A$2163,A33,'Soporte SRY'!$R$4:$R$2163)/COUNTIFS('Soporte SRY'!$A$4:$A$2163,A33,'Soporte SRY'!$Q$4:$Q$2163,"Falla")) -> 0.72222222 | I33: =SUMIF('Soporte SRY'!$A$4:$A$2163,A33,'Soporte SRY'!$O$4:$O$2163) -> 745.86763
A34: ="SRY-4-3" -> SRY-4-3 | B34: =$B$11 -> 5 | C34: =$E$10 -> 1.25 | D34: =COUNTIFS('Soporte SRY'!$A$4:$A$2163,A34,'Soporte SRY'!$Q$4:$Q$2163,"Satisfactorio")/$E$13 -> 0.58333333 | E34: =SUMIF('Soporte SRY'!$A$4:$A$2163,A34,'Soporte SRY'!$P$4:$P$2163) -> 224.28933 | F34: =IF(SUMIF('Soporte SRY'!$A$4:$A$2163,A34,'Soporte SRY'!$S$4:$S$2163)=0,0,E34/SUMIF('Soporte SRY'!$A$4:$A$2163,A34,'Soporte SRY'!$S$4:$S$2163)) -> 10.680444 | G34: =IF(SUMIF('Soporte SRY'!$A$4:$A$2163,A34,'Soporte SRY'!$S$4:$S$2163)=0,0,COUNTIFS('Soporte SRY'!$A$4:$A$2163,A34,'Soporte SRY'!$Q$4:$Q$2163,"Falla")/SUMIF('Soporte SRY'!$A$4:$A$2163,A34,'Soporte SRY'!$S$4:$S$2163)) -> 2.3809524 | H34: =IF(COUNTIFS('Soporte SRY'!$A$4:$A$2163,A34,'Soporte SRY'!$Q$4:$Q$2163,"Falla")=0,1,SUMIF('Soporte SRY'!$A$4:$A$2163,A34,'Soporte SRY'!$R$4:$R$2163)/COUNTIFS('Soporte SRY'!$A$4:$A$2163,A34,'Soporte SRY'!$Q$4:$Q$2163,"Falla")) -> 0.4 | I34: =SUMIF('Soporte SRY'!$A$4:$A$2163,A34,'Soporte SRY'!$O$4:$O$2163) -> 526.82233
A35: ="SRY-5-1" -> SRY-5-1 | B35: =$B$12 -> 10 | C35: =$E$8 -> 0.75 | D35: =COUNTIFS('Soporte SRY'!$A$4:$A$2163,A35,'Soporte SRY'!$Q$4:$Q$2163,"Satisfactorio")/$E$13 -> 1 | E35: =SUMIF('Soporte SRY'!$A$4:$A$2163,A35,'Soporte SRY'!$P$4:$P$2163) -> 0 | F35: =IF(SUMIF('Soporte SRY'!$A$4:$A$2163,A35,'Soporte SRY'!$S$4:$S$2163)=0,0,E35/SUMIF('Soporte SRY'!$A$4:$A$2163,A35,'Soporte SRY'!$S$4:$S$2163)) -> 0 | G35: =IF(SUMIF('Soporte SRY'!$A$4:$A$2163,A35,'Soporte SRY'!$S$4:$S$2163)=0,0,COUNTIFS('Soporte SRY'!$A$4:$A$2163,A35,'Soporte SRY'!$Q$4:$Q$2163,"Falla")/SUMIF('Soporte SRY'!$A$4:$A$2163,A35,'Soporte SRY'!$S$4:$S$2163)) -> 0 | H35: =IF(COUNTIFS('Soporte SRY'!$A$4:$A$2163,A35,'Soporte SRY'!$Q$4:$Q$2163,"Falla")=0,1,SUMIF('Soporte SRY'!$A$4:$A$2163,A35,'Soporte SRY'!$R$4:$R$2163)/COUNTIFS('Soporte SRY'!$A$4:$A$2163,A35,'Soporte SRY'!$Q$4:$Q$2163,"Falla")) -> 1 | I35: =SUMIF('Soporte SRY'!$A$4:$A$2163,A35,'Soporte SRY'!$O$4:$O$2163) -> 1100.4628
A36: ="SRY-5-2" -> SRY-5-2 | B36: =$B$12 -> 10 | C36: =$E$9 -> 1 | D36: =COUNTIFS('Soporte SRY'!$A$4:$A$2163,A36,'Soporte SRY'!$Q$4:$Q$2163,"Satisfactorio")/$E$13 -> 0.975 | E36: =SUMIF('Soporte SRY'!$A$4:$A$2163,A36,'Soporte SRY'!$P$4:$P$2163) -> 5.2875716 | F36: =IF(SUMIF('Soporte SRY'!$A$4:$A$2163,A36,'Soporte SRY'!$S$4:$S$2163)=0,0,E36/SUMIF('Soporte SRY'!$A$4:$A$2163,A36,'Soporte SRY'!$S$4:$S$2163)) -> 2.6437858 | G36: =IF(SUMIF('Soporte SRY'!$A$4:$A$2163,A36,'Soporte SRY'!$S$4:$S$2163)=0,0,COUNTIFS('Soporte SRY'!$A$4:$A$2163,A36,'Soporte SRY'!$Q$4:$Q$2163,"Falla")/SUMIF('Soporte SRY'!$A$4:$A$2163,A36,'Soporte SRY'!$S$4:$S$2163)) -> 1.5 | H36: =IF(COUNTIFS('Soporte SRY'!$A$4:$A$2163,A36,'Soporte SRY'!$Q$4:$Q$2163,"Falla")=0,1,SUMIF('Soporte SRY'!$A$4:$A$2163,A36,'Soporte SRY'!$R$4:$R$2163)/COUNTIFS('Soporte SRY'!$A$4:$A$2163,A36,'Soporte SRY'!$Q$4:$Q$2163,"Falla")) -> 0.66666667 | I36: =SUMIF('Soporte SRY'!$A$4:$A$2163,A36,'Soporte SRY'!$O$4:$O$2163) -> 700.68151
A37: ="SRY-5-3" -> SRY-5-3 | B37: =$B$12 -> 10 | C37: =$E$10 -> 1.25 | D37: =COUNTIFS('Soporte SRY'!$A$4:$A$2163,A37,'Soporte SRY'!$Q$4:$Q$2163,"Satisfactorio")/$E$13 -> 0.725 | E37: =SUMIF('Soporte SRY'!$A$4:$A$2163,A37,'Soporte SRY'!$P$4:$P$2163) -> 132.02849 | F37: =IF(SUMIF('Soporte SRY'!$A$4:$A$2163,A37,'Soporte SRY'!$S$4:$S$2163)=0,0,E37/SUMIF('Soporte SRY'!$A$4:$A$2163,A37,'Soporte SRY'!$S$4:$S$2163)) -> 6.9488677 | G37: =IF(SUMIF('Soporte SRY'!$A$4:$A$2163,A37,'Soporte SRY'!$S$4:$S$2163)=0,0,COUNTIFS('Soporte SRY'!$A$4:$A$2163,A37,'Soporte SRY'!$Q$4:$Q$2163,"Falla")/SUMIF('Soporte SRY'!$A$4:$A$2163,A37,'Soporte SRY'!$S$4:$S$2163)) -> 1.7368421 | H37: =IF(COUNTIFS('Soporte SRY'!$A$4:$A$2163,A37,'Soporte SRY'!$Q$4:$Q$2163,"Falla")=0,1,SUMIF('Soporte SRY'!$A$4:$A$2163,A37,'Soporte SRY'!$R$4:$R$2163)/COUNTIFS('Soporte SRY'!$A$4:$A$2163,A37,'Soporte SRY'!$Q$4:$Q$2163,"Falla")) -> 0.57575758 | I37: =SUMIF('Soporte SRY'!$A$4:$A$2163,A37,'Soporte SRY'!$O$4:$O$2163) -> 424.3438
